<?xml version="1.0" ?>
<robot xmlns:xacro="http://www.ros.org/wiki/xacro" name="mobile_platform">

    <!--Include files-->
    <xacro:include filename="gazebo.xacro" />
    <xacro:include filename="inertias.xacro" />
    <xacro:include filename="materials.xacro" />

    <!--Define properties-->
    <!-- <xacro:property name="width" value="1" /> -->

    <!--MACROS-->
    <!-- Simple box link  -->
    <xacro:macro name="box_link" params="name length width height material inertial:=true">
        <link name="${name}_link">
            <visual>
                <geometry>
                    <box size="${length} ${width} ${height}"/>
                </geometry>
                <material name="${material}"/>
            </visual>
            <collision>
                <geometry>
                    <box size="${length} ${width} ${height}"/>
                </geometry>
            </collision>

            <!-- Physical properties -->
            <xacro:if value="${inertial}">
                <xacro:box_inertial x="${length}" y="${width}" z="${height}" mass="0.1"/>
            </xacro:if>
        </link>
    </xacro:macro>

    <!-- Simple revolute joint -->
    <xacro:macro name="revolute_joint" params="name parent_name child_name origin axis">
        <joint name="${name}_joint" type="revolute">
            <parent link="${parent_name}_link"/>
            <child link="${child_name}_link"/>
            <origin xyz="${origin}"/>
            <axis xyz="${axis}"/>
            <limit upper="1.57" lower="-1.57" effort="500" velocity="10"/>
            <dynamics damping="0.1" friction="0.1"/>
        </joint>
    </xacro:macro>

    <!-- Simple prismatic joint -->
    <xacro:macro name="prismatic_joint" params="name parent_name child_name origin axis">
        <joint name="${name}_joint" type="prismatic">
            <parent link="${parent_name}_link"/>
            <child link="${child_name}_link"/>
            <origin xyz="${origin}"/>
            <axis xyz="${axis}"/>
            <limit upper="3.0" lower="-3.0" effort="500" velocity="10"/>
            <dynamics damping="0.1" friction="0.1"/>
        </joint>
    </xacro:macro>

    <!-- Transmission tags to actuate the platform -->
    <!-- It links an actuator to a joint -->
    <xacro:macro name="transmission" params="joint_name">
        <transmission name="${joint_name}_transmission">
            <type>transmission_interface/SimpleTransmission</type>

            <joint name="${joint_name}_joint">
                <!-- We can change the hardware interface to control position, velocity or effort -->
                <hardwareInterface>hardware_interface/PositionJointInterface</hardwareInterface>
            </joint>

            <actuator name="${joint_name}_actuator">
                <hardwareInterface>hardware_interface/PositionJointInterface</hardwareInterface>
                <mechanicalReduction>1</mechanicalReduction>
            </actuator>
        </transmission>
    </xacro:macro>


    <!-- Robot description -->
    <!-- Links -->
    <link name="world"/>
    
    <xacro:box_link name="base_tx" length="0" width="0" height="0" material="red"/>
    <xacro:box_link name="base_ty" length="0" width="0" height="0" material="red"/>
    <xacro:box_link name="base_tz" length="0" width="0" height="0" material="red"/>
    <xacro:box_link name="base_yaw" length="0" width="0" height="0" material="red"/>
    <xacro:box_link name="base_pitch" length="0" width="0" height="0" material="red"/>
    <xacro:box_link name="base_roll" length="0" width="0" height="0" material="red"/>
    <xacro:box_link name="board" length="1" width="1" height="0.05" material="green"/>
 
    <!-- Joints -->
    <joint name="fixed" type="fixed">
        <parent link="world"/>
        <child link="base_tx_link"/>
        <origin xyz="0 0 1."/>
    </joint>

    <xacro:prismatic_joint name="tx" parent_name="base_tx" child_name="base_ty" origin="0 0 0" axis="1 0 0"/>
    <xacro:prismatic_joint name="ty" parent_name="base_ty" child_name="base_tz" origin="0 0 0" axis="0 1 0"/>
    <xacro:prismatic_joint name="tz" parent_name="base_tz" child_name="base_yaw" origin="0 0 0" axis="0 0 1"/>
    <xacro:revolute_joint name="yaw" parent_name="base_yaw" child_name="base_pitch" origin="0 0 0" axis="0 0 1"/>
    <xacro:revolute_joint name="pitch" parent_name="base_pitch" child_name="base_roll" origin="0 0 0" axis="0 1 0"/>
    <xacro:revolute_joint name="roll" parent_name="base_roll" child_name="board" origin="0 0 0" axis="1 0 0"/>

    <!-- Transmissions -->
    <xacro:transmission joint_name="tx"/>
    <xacro:transmission joint_name="ty"/>
    <xacro:transmission joint_name="tz"/>
    <xacro:transmission joint_name="roll"/>
    <xacro:transmission joint_name="pitch"/>
    <xacro:transmission joint_name="yaw"/>
    
</robot>
