<?xml version="1.0" ?>
<!-- =================================================================================== -->
<!-- |    This document was autogenerated by xacro from mobile_platform.xacro          | -->
<!-- |    EDITING THIS FILE BY HAND IS NOT RECOMMENDED                                 | -->
<!-- =================================================================================== -->
<robot name="mobile_platform">
  <!-- <xacro:property name="M_PI" value="3.1415926535897931" /> -->
  <material name="red">
    <color rgba="1 0 0 1"/>
  </material>
  <material name="green">
    <color rgba="0 1 0 1"/>
  </material>
  <!--Define properties-->
  <!-- <xacro:property name="width" value="1" /> -->
  <link name="ground_link">
    <visual>
      <geometry>
        <box size="0.1 0.1 0.1"/>
      </geometry>
      <material name="green"/>
    </visual>
    <collision>
      <geometry>
        <box size="0.1 0.1 0.1"/>
      </geometry>
    </collision>
    <inertial>
      <mass value="1"/>
      <inertia ixx="0.0016666660000000002" ixy="0.0" ixz="0.0" iyy="0.0016666660000000002" iyz="0.0" izz="0.0016666660000000002"/>
    </inertial>
  </link>
  <link name="board_link">
    <visual>
      <geometry>
        <box size="1 1 0.05"/>
      </geometry>
      <material name="red"/>
    </visual>
    <collision>
      <geometry>
        <box size="1 1 0.05"/>
      </geometry>
    </collision>
    <inertial>
      <mass value="1"/>
      <inertia ixx="0.08354163325" ixy="0.0" ixz="0.0" iyy="0.08354163325" iyz="0.0" izz="0.1666666"/>
    </inertial>
  </link>
  <joint name="roll_revolute_joint" type="revolute">
    <parent link="ground_link"/>
    <child link="board_link"/>
    <origin xyz="0 0 1"/>
    <axis xyz="1 0 0"/>
    <limit effort="1" lower="-1.57" upper="1.57" velocity="0.1"/>
    <dynamics damping="0.1" friction="0.1"/>
  </joint>
</robot>

